<?xml version='1.0' encoding='UTF-8'?>
<robot name="Model_0">
  <link name="base_link">
    <inertial>
      <origin xyz="0.0 0.0 0.0" rpy="0.0 -0.0 0.0"/>
      <mass value="1.0"/>
      <inertia ixx="1.0" ixy="0.0" ixz="0.0" iyy="1.0" iyz="0.0" izz="1.0"/>
    </inertial>
    <visual>
      <geometry>
        <box size="0.67 0.67 0.3 "/>
      </geometry>
      <material name="red"/>
      <origin xyz="0.0 0.0 0.0" rpy="0.0 -0.0 0.0"/>
    </visual>
    <collision>
      <geometry>
        <box size="0.67 0.67 0.3 "/>
      </geometry>
      <origin xyz="0.0 0.0 0.0" rpy="0.0 0.0 0.0"/>
    </collision>
  </link>
  <link name="arm_0_arm1">
    <inertial>
      <origin xyz="0.0 0.34 0.0" rpy="0.0 0.0 0.0"/>
      <mass value="1.0"/>
      <inertia ixx="0.0" ixy="0.0" ixz="0.0" iyy="0.0" iyz="0.0" izz="0.0"/>
    </inertial>
    <visual>
      <geometry>
        <box size="0.67 0.67 0.3 "/>
      </geometry>
      <origin xyz="0.0 0.34 0.0" rpy="0.0 0.0 0.0"/>
    </visual>
    <collision>
      <geometry>
        <box size="0.67 0.67 0.3 "/>
      </geometry>
      <origin xyz="0.0 0.34 0.0" rpy="0.0 0.0 0.0"/>
    </collision>
  </link>
  <link name="arm_0_arm2">
    <inertial>
      <origin xyz="0.0 0.34 0.0" rpy="0.0 0.0 0.0"/>
      <mass value="1.0"/>
      <inertia ixx="0.0" ixy="0.0" ixz="0.0" iyy="0.0" iyz="0.0" izz="0.0"/>
    </inertial>
    <visual>
      <geometry>
        <box size="0.67 0.67 0.3 "/>
      </geometry>
      <origin xyz="0.0 0.34 0.0" rpy="0.0 0.0 0.0"/>
    </visual>
    <collision>
      <geometry>
        <box size="0.67 0.67 0.3 "/>
      </geometry>
      <origin xyz="0.0 0.34 0.0" rpy="0.0 0.0 0.0"/>
    </collision>
  </link>
  <link name="arm_1_arm1">
    <inertial>
      <origin xyz="0.0 0.34 0.0" rpy="0.0 0.0 0.0"/>
      <mass value="1.0"/>
      <inertia ixx="0.0" ixy="0.0" ixz="0.0" iyy="0.0" iyz="0.0" izz="0.0"/>
    </inertial>
    <visual>
      <geometry>
        <box size="0.67 0.67 0.3 "/>
      </geometry>
      <origin xyz="0.0 0.34 0.0" rpy="0.0 0.0 0.0"/>
    </visual>
    <collision>
      <geometry>
        <box size="0.67 0.67 0.3 "/>
      </geometry>
      <origin xyz="0.0 0.34 0.0" rpy="0.0 0.0 0.0"/>
    </collision>
  </link>
  <link name="arm_1_arm2">
    <inertial>
      <origin xyz="0.0 0.34 0.0" rpy="0.0 0.0 0.0"/>
      <mass value="1.0"/>
      <inertia ixx="0.0" ixy="0.0" ixz="0.0" iyy="0.0" iyz="0.0" izz="0.0"/>
    </inertial>
    <visual>
      <geometry>
        <box size="0.67 0.67 0.3 "/>
      </geometry>
      <origin xyz="0.0 0.34 0.0" rpy="0.0 0.0 0.0"/>
    </visual>
    <collision>
      <geometry>
        <box size="0.67 0.67 0.3 "/>
      </geometry>
      <origin xyz="0.0 0.34 0.0" rpy="0.0 0.0 0.0"/>
    </collision>
  </link>
  <link name="arm_2_arm1">
    <inertial>
      <origin xyz="0.0 0.34 0.0" rpy="0.0 0.0 0.0"/>
      <mass value="1.0"/>
      <inertia ixx="0.0" ixy="0.0" ixz="0.0" iyy="0.0" iyz="0.0" izz="0.0"/>
    </inertial>
    <visual>
      <geometry>
        <box size="0.67 0.67 0.3 "/>
      </geometry>
      <origin xyz="0.0 0.34 0.0" rpy="0.0 0.0 0.0"/>
    </visual>
    <collision>
      <geometry>
        <box size="0.67 0.67 0.3 "/>
      </geometry>
      <origin xyz="0.0 0.34 0.0" rpy="0.0 0.0 0.0"/>
    </collision>
  </link>
  <link name="arm_2_arm2">
    <inertial>
      <origin xyz="0.0 0.34 0.0" rpy="0.0 0.0 0.0"/>
      <mass value="1.0"/>
      <inertia ixx="0.0" ixy="0.0" ixz="0.0" iyy="0.0" iyz="0.0" izz="0.0"/>
    </inertial>
    <visual>
      <geometry>
        <box size="0.67 0.67 0.3 "/>
      </geometry>
      <origin xyz="0.0 0.34 0.0" rpy="0.0 0.0 0.0"/>
    </visual>
    <collision>
      <geometry>
        <box size="0.67 0.67 0.3 "/>
      </geometry>
      <origin xyz="0.0 0.34 0.0" rpy="0.0 0.0 0.0"/>
    </collision>
  </link>
  <link name="arm_3_arm1">
    <inertial>
      <origin xyz="0.0 0.34 0.0" rpy="0.0 0.0 0.0"/>
      <mass value="1.0"/>
      <inertia ixx="0.0" ixy="0.0" ixz="0.0" iyy="0.0" iyz="0.0" izz="0.0"/>
    </inertial>
    <visual>
      <geometry>
        <box size="0.67 0.67 0.3 "/>
      </geometry>
      <origin xyz="0.0 0.34 0.0" rpy="0.0 0.0 0.0"/>
    </visual>
    <collision>
      <geometry>
        <box size="0.67 0.67 0.3 "/>
      </geometry>
      <origin xyz="0.0 0.34 0.0" rpy="0.0 0.0 0.0"/>
    </collision>
  </link>
  <link name="arm_3_arm2">
    <inertial>
      <origin xyz="0.0 0.34 0.0" rpy="0.0 0.0 0.0"/>
      <mass value="1.0"/>
      <inertia ixx="0.0" ixy="0.0" ixz="0.0" iyy="0.0" iyz="0.0" izz="0.0"/>
    </inertial>
    <visual>
      <geometry>
        <box size="0.67 0.67 0.3 "/>
      </geometry>
      <origin xyz="0.0 0.34 0.0" rpy="0.0 0.0 0.0"/>
    </visual>
    <collision>
      <geometry>
        <box size="0.67 0.67 0.3 "/>
      </geometry>
      <origin xyz="0.0 0.34 0.0" rpy="0.0 0.0 0.0"/>
    </collision>
  </link>
  <joint name="arm_0_jointBase" type="fixed">
    <limit effort="1.0" velocity="1.0" lower="-1.0" upper="1.0"/>
    <parent link="base_link"/>
    <child link="arm_0_arm1"/>
    <axis xyz="1. 0. 0."/>
    <origin xyz="0.46 -0.47 -0.02" rpy="-2.78 0.0 -1.56"/>
  </joint>
  <joint name="arm_0_joint1" type="revolute">
    <limit effort="1.0" velocity="1.0" lower="-1.0" upper="1.0"/>
    <parent link="arm_0_arm1"/>
    <child link="arm_0_arm2"/>
    <axis xyz="1. 0. 0."/>
    <origin xyz="0.0 0.68 0.0" rpy="0.0 0.0 0.0"/>
  </joint>
  <joint name="arm_1_jointBase" type="fixed">
    <limit effort="1.0" velocity="1.0" lower="-1.0" upper="1.0"/>
    <parent link="base_link"/>
    <child link="arm_1_arm1"/>
    <axis xyz="1. 0. 0."/>
    <origin xyz="-0.43 -0.36 0.06" rpy="-3.023185307179587 0.0 1.41"/>
  </joint>
  <joint name="arm_1_joint1" type="revolute">
    <limit effort="1.0" velocity="1.0" lower="-1.0" upper="1.0"/>
    <parent link="arm_1_arm1"/>
    <child link="arm_1_arm2"/>
    <axis xyz="1. 0. 0."/>
    <origin xyz="0.0 0.68 0.0" rpy="0.0 0.0 0.0"/>
  </joint>
  <joint name="arm_2_jointBase" type="fixed">
    <limit effort="1.0" velocity="1.0" lower="-1.0" upper="1.0"/>
    <parent link="base_link"/>
    <child link="arm_2_arm1"/>
    <axis xyz="1. 0. 0."/>
    <origin xyz="0.29 0.43 0.0" rpy="3.0531853071795867 0.0 -1.76"/>
  </joint>
  <joint name="arm_2_joint1" type="revolute">
    <limit effort="1.0" velocity="1.0" lower="-1.0" upper="1.0"/>
    <parent link="arm_2_arm1"/>
    <child link="arm_2_arm2"/>
    <axis xyz="1. 0. 0."/>
    <origin xyz="0.0 0.68 0.0" rpy="0.0 0.0 0.0"/>
  </joint>
  <joint name="arm_3_jointBase" type="fixed">
    <limit effort="1.0" velocity="1.0" lower="-1.0" upper="1.0"/>
    <parent link="base_link"/>
    <child link="arm_3_arm1"/>
    <axis xyz="1. 0. 0."/>
    <origin xyz="0.39 0.4 0.06" rpy="-2.17 0.0 -1.49"/>
  </joint>
  <joint name="arm_3_joint1" type="revolute">
    <limit effort="1.0" velocity="1.0" lower="-1.0" upper="1.0"/>
    <parent link="arm_3_arm1"/>
    <child link="arm_3_arm2"/>
    <axis xyz="1. 0. 0."/>
    <origin xyz="0.0 0.68 0.0" rpy="0.0 0.0 0.0"/>
  </joint>
  <material name="red">
    <color rgba="0.969 0.129 0.122 1.   "/>
  </material>
</robot>
