<?xml version='1.0' encoding='UTF-8'?>
<robot name="Model_1">
  <link name="base_link">
    <inertial>
      <origin xyz="0.0 0.0 0.0" rpy="0.0 -0.0 0.0"/>
      <mass value="1.0"/>
      <inertia ixx="1.0" ixy="0.0" ixz="0.0" iyy="1.0" iyz="0.0" izz="1.0"/>
    </inertial>
    <visual>
      <geometry>
        <box size="0.67 0.67 0.3 "/>
      </geometry>
      <origin xyz="0.0 0.0 0.0" rpy="0.0 -0.0 0.0"/>
    </visual>
    <collision>
      <geometry>
        <box size="0.67 0.67 0.3 "/>
      </geometry>
      <origin xyz="0.0 0.0 0.0" rpy="0.0 0.0 0.0"/>
    </collision>
  </link>
  <link name="arm0">
    <inertial>
      <origin xyz="-0.2754139099504469 -0.5072055461293885 0.024392107765183926" rpy="0.46795266481401376 -0.35131559449541583 -0.8876677875417978"/>
      <mass value="1.0"/>
      <inertia ixx="0.0" ixy="0.0" ixz="0.0" iyy="0.0" iyz="0.0" izz="0.0"/>
    </inertial>
    <visual>
      <geometry>
        <box size="0.67 0.67 0.3 "/>
      </geometry>
      <origin xyz="-0.2754139099504469 -0.5072055461293885 0.024392107765183926" rpy="0.46795266481401376 -0.35131559449541583 -0.8876677875417978"/>
    </visual>
    <collision>
      <geometry>
        <box size="0.67 0.67 0.3 "/>
      </geometry>
      <origin xyz="-0.2754139099504469 -0.5072055461293885 0.024392107765183926" rpy="0.46795266481401376 -0.35131559449541583 -0.8876677875417978"/>
    </collision>
  </link>
  <link name="arm1">
    <inertial>
      <origin xyz="0.44778048549975424 0.46529045892497667 -0.06288045819785076" rpy="0.9356450512879118 0.2631307903209472 -0.2827084637495376"/>
      <mass value="1.0"/>
      <inertia ixx="0.0" ixy="0.0" ixz="0.0" iyy="0.0" iyz="0.0" izz="0.0"/>
    </inertial>
    <visual>
      <geometry>
        <box size="0.67 0.67 0.3 "/>
      </geometry>
      <origin xyz="0.44778048549975424 0.46529045892497667 -0.06288045819785076" rpy="0.9356450512879118 0.2631307903209472 -0.2827084637495376"/>
    </visual>
    <collision>
      <geometry>
        <box size="0.67 0.67 0.3 "/>
      </geometry>
      <origin xyz="0.44778048549975424 0.46529045892497667 -0.06288045819785076" rpy="0.9356450512879118 0.2631307903209472 -0.2827084637495376"/>
    </collision>
  </link>
  <link name="arm2">
    <inertial>
      <origin xyz="-0.3587290330224046 0.1816545161496841 0.022898794935481234" rpy="-0.5951788152823636 -0.5571220521929414 0.30080080395032827"/>
      <mass value="1.0"/>
      <inertia ixx="0.0" ixy="0.0" ixz="0.0" iyy="0.0" iyz="0.0" izz="0.0"/>
    </inertial>
    <visual>
      <geometry>
        <box size="0.67 0.67 0.3 "/>
      </geometry>
      <origin xyz="-0.3587290330224046 0.1816545161496841 0.022898794935481234" rpy="-0.5951788152823636 -0.5571220521929414 0.30080080395032827"/>
    </visual>
    <collision>
      <geometry>
        <box size="0.67 0.67 0.3 "/>
      </geometry>
      <origin xyz="-0.3587290330224046 0.1816545161496841 0.022898794935481234" rpy="-0.5951788152823636 -0.5571220521929414 0.30080080395032827"/>
    </collision>
  </link>
  <joint name="0" type="revolute">
    <limit effort="1.0" velocity="1.0" lower="-1.0" upper="1.0"/>
    <parent link="base_link"/>
    <child link="arm0"/>
    <axis xyz="1. 0. 0."/>
    <origin xyz="-0.2754139099504469 -0.5072055461293885 0.024392107765183926" rpy="0.46795266481401376 -0.35131559449541583 -0.8876677875417978"/>
  </joint>
  <joint name="1" type="revolute">
    <limit effort="1.0" velocity="1.0" lower="-1.0" upper="1.0"/>
    <parent link="base_link"/>
    <child link="arm1"/>
    <axis xyz="1. 0. 0."/>
    <origin xyz="0.44778048549975424 0.46529045892497667 -0.06288045819785076" rpy="0.9356450512879118 0.2631307903209472 -0.2827084637495376"/>
  </joint>
  <joint name="2" type="revolute">
    <limit effort="1.0" velocity="1.0" lower="-1.0" upper="1.0"/>
    <parent link="base_link"/>
    <child link="arm2"/>
    <axis xyz="1. 0. 0."/>
    <origin xyz="-0.3587290330224046 0.1816545161496841 0.022898794935481234" rpy="-0.5951788152823636 -0.5571220521929414 0.30080080395032827"/>
  </joint>
</robot>
