<?xml version='1.0' encoding='UTF-8'?>
<robot name="Model_0">
  <link name="base_link">
    <inertial>
      <origin xyz="0.0 0.0 0.0" rpy="0.0 -0.0 0.0"/>
      <mass value="1.0"/>
      <inertia ixx="1.0" ixy="0.0" ixz="0.0" iyy="1.0" iyz="0.0" izz="1.0"/>
    </inertial>
    <visual>
      <geometry>
        <box size="0.67 0.67 0.3 "/>
      </geometry>
      <material name="red"/>
      <origin xyz="0.0 0.0 0.0" rpy="0.0 -0.0 0.0"/>
    </visual>
    <collision>
      <geometry>
        <box size="0.67 0.67 0.3 "/>
      </geometry>
      <origin xyz="0.0 0.0 0.0" rpy="0.0 0.0 0.0"/>
    </collision>
  </link>
  <link name="arm_0_arm1">
    <inertial>
      <origin xyz="0.0 0.34 0.0" rpy="0.0 0.0 0.0"/>
      <mass value="1.0"/>
      <inertia ixx="0.0" ixy="0.0" ixz="0.0" iyy="0.0" iyz="0.0" izz="0.0"/>
    </inertial>
    <visual>
      <geometry>
        <box size="0.67 0.67 0.3 "/>
      </geometry>
      <origin xyz="0.0 0.34 0.0" rpy="0.0 0.0 0.0"/>
    </visual>
    <collision>
      <geometry>
        <box size="0.67 0.67 0.3 "/>
      </geometry>
      <origin xyz="0.0 0.34 0.0" rpy="0.0 0.0 0.0"/>
    </collision>
  </link>
  <link name="arm_0_arm2">
    <inertial>
      <origin xyz="0.0 0.34 0.0" rpy="0.0 0.0 0.0"/>
      <mass value="1.0"/>
      <inertia ixx="0.0" ixy="0.0" ixz="0.0" iyy="0.0" iyz="0.0" izz="0.0"/>
    </inertial>
    <visual>
      <geometry>
        <box size="0.67 0.67 0.3 "/>
      </geometry>
      <origin xyz="0.0 0.34 0.0" rpy="0.0 0.0 0.0"/>
    </visual>
    <collision>
      <geometry>
        <box size="0.67 0.67 0.3 "/>
      </geometry>
      <origin xyz="0.0 0.34 0.0" rpy="0.0 0.0 0.0"/>
    </collision>
  </link>
  <link name="arm_1_arm1">
    <inertial>
      <origin xyz="0.0 0.34 0.0" rpy="0.0 0.0 0.0"/>
      <mass value="1.0"/>
      <inertia ixx="0.0" ixy="0.0" ixz="0.0" iyy="0.0" iyz="0.0" izz="0.0"/>
    </inertial>
    <visual>
      <geometry>
        <box size="0.67 0.67 0.3 "/>
      </geometry>
      <origin xyz="0.0 0.34 0.0" rpy="0.0 0.0 0.0"/>
    </visual>
    <collision>
      <geometry>
        <box size="0.67 0.67 0.3 "/>
      </geometry>
      <origin xyz="0.0 0.34 0.0" rpy="0.0 0.0 0.0"/>
    </collision>
  </link>
  <link name="arm_1_arm2">
    <inertial>
      <origin xyz="0.0 0.34 0.0" rpy="0.0 0.0 0.0"/>
      <mass value="1.0"/>
      <inertia ixx="0.0" ixy="0.0" ixz="0.0" iyy="0.0" iyz="0.0" izz="0.0"/>
    </inertial>
    <visual>
      <geometry>
        <box size="0.67 0.67 0.3 "/>
      </geometry>
      <origin xyz="0.0 0.34 0.0" rpy="0.0 0.0 0.0"/>
    </visual>
    <collision>
      <geometry>
        <box size="0.67 0.67 0.3 "/>
      </geometry>
      <origin xyz="0.0 0.34 0.0" rpy="0.0 0.0 0.0"/>
    </collision>
  </link>
  <link name="arm_2_arm1">
    <inertial>
      <origin xyz="0.0 0.34 0.0" rpy="0.0 0.0 0.0"/>
      <mass value="1.0"/>
      <inertia ixx="0.0" ixy="0.0" ixz="0.0" iyy="0.0" iyz="0.0" izz="0.0"/>
    </inertial>
    <visual>
      <geometry>
        <box size="0.67 0.67 0.3 "/>
      </geometry>
      <origin xyz="0.0 0.34 0.0" rpy="0.0 0.0 0.0"/>
    </visual>
    <collision>
      <geometry>
        <box size="0.67 0.67 0.3 "/>
      </geometry>
      <origin xyz="0.0 0.34 0.0" rpy="0.0 0.0 0.0"/>
    </collision>
  </link>
  <link name="arm_2_arm2">
    <inertial>
      <origin xyz="0.0 0.34 0.0" rpy="0.0 0.0 0.0"/>
      <mass value="1.0"/>
      <inertia ixx="0.0" ixy="0.0" ixz="0.0" iyy="0.0" iyz="0.0" izz="0.0"/>
    </inertial>
    <visual>
      <geometry>
        <box size="0.67 0.67 0.3 "/>
      </geometry>
      <origin xyz="0.0 0.34 0.0" rpy="0.0 0.0 0.0"/>
    </visual>
    <collision>
      <geometry>
        <box size="0.67 0.67 0.3 "/>
      </geometry>
      <origin xyz="0.0 0.34 0.0" rpy="0.0 0.0 0.0"/>
    </collision>
  </link>
  <link name="arm_3_arm1">
    <inertial>
      <origin xyz="0.0 0.34 0.0" rpy="0.0 0.0 0.0"/>
      <mass value="1.0"/>
      <inertia ixx="0.0" ixy="0.0" ixz="0.0" iyy="0.0" iyz="0.0" izz="0.0"/>
    </inertial>
    <visual>
      <geometry>
        <box size="0.67 0.67 0.3 "/>
      </geometry>
      <origin xyz="0.0 0.34 0.0" rpy="0.0 0.0 0.0"/>
    </visual>
    <collision>
      <geometry>
        <box size="0.67 0.67 0.3 "/>
      </geometry>
      <origin xyz="0.0 0.34 0.0" rpy="0.0 0.0 0.0"/>
    </collision>
  </link>
  <link name="arm_3_arm2">
    <inertial>
      <origin xyz="0.0 0.34 0.0" rpy="0.0 0.0 0.0"/>
      <mass value="1.0"/>
      <inertia ixx="0.0" ixy="0.0" ixz="0.0" iyy="0.0" iyz="0.0" izz="0.0"/>
    </inertial>
    <visual>
      <geometry>
        <box size="0.67 0.67 0.3 "/>
      </geometry>
      <origin xyz="0.0 0.34 0.0" rpy="0.0 0.0 0.0"/>
    </visual>
    <collision>
      <geometry>
        <box size="0.67 0.67 0.3 "/>
      </geometry>
      <origin xyz="0.0 0.34 0.0" rpy="0.0 0.0 0.0"/>
    </collision>
  </link>
  <joint name="arm_0_jointBase" type="fixed">
    <limit effort="1.0" velocity="1.0" lower="-1.0" upper="1.0"/>
    <parent link="base_link"/>
    <child link="arm_0_arm1"/>
    <axis xyz="1. 0. 0."/>
    <origin xyz="-0.5180408406284394 0.3328807191946399 0.016876017309966018" rpy="-0.7343782183005417 0.5204430992311809 3.032704424841325"/>
  </joint>
  <joint name="arm_0_joint1" type="revolute">
    <limit effort="1.0" velocity="1.0" lower="-1.0" upper="1.0"/>
    <parent link="arm_0_arm1"/>
    <child link="arm_0_arm2"/>
    <axis xyz="1. 0. 0."/>
    <origin xyz="0.0 0.68 0.0" rpy="0.0 0.0 0.0"/>
  </joint>
  <joint name="arm_1_jointBase" type="fixed">
    <limit effort="1.0" velocity="1.0" lower="-1.0" upper="1.0"/>
    <parent link="base_link"/>
    <child link="arm_1_arm1"/>
    <axis xyz="1. 0. 0."/>
    <origin xyz="0.876759394275336 -0.7617713583382739 -0.04201582095389918" rpy="-0.3315103960319715 1.10424615188475 -1.574280653352407"/>
  </joint>
  <joint name="arm_1_joint1" type="revolute">
    <limit effort="1.0" velocity="1.0" lower="-1.0" upper="1.0"/>
    <parent link="arm_1_arm1"/>
    <child link="arm_1_arm2"/>
    <axis xyz="1. 0. 0."/>
    <origin xyz="0.0 0.68 0.0" rpy="0.0 0.0 0.0"/>
  </joint>
  <joint name="arm_2_jointBase" type="fixed">
    <limit effort="1.0" velocity="1.0" lower="-1.0" upper="1.0"/>
    <parent link="base_link"/>
    <child link="arm_2_arm1"/>
    <axis xyz="1. 0. 0."/>
    <origin xyz="0.6994780266781575 -0.08463747082461448 -0.012652610811970305" rpy="-0.9494390452294184 1.0525055573459374 0.24137262003992532"/>
  </joint>
  <joint name="arm_2_joint1" type="revolute">
    <limit effort="1.0" velocity="1.0" lower="-1.0" upper="1.0"/>
    <parent link="arm_2_arm1"/>
    <child link="arm_2_arm2"/>
    <axis xyz="1. 0. 0."/>
    <origin xyz="0.0 0.68 0.0" rpy="0.0 0.0 0.0"/>
  </joint>
  <joint name="arm_3_jointBase" type="fixed">
    <limit effort="1.0" velocity="1.0" lower="-1.0" upper="1.0"/>
    <parent link="base_link"/>
    <child link="arm_3_arm1"/>
    <axis xyz="1. 0. 0."/>
    <origin xyz="0.7588911572714849 -0.551340219886647 0.06383018230729082" rpy="2.0721282346627112 -0.01314200428149238 2.676053116649309"/>
  </joint>
  <joint name="arm_3_joint1" type="revolute">
    <limit effort="1.0" velocity="1.0" lower="-1.0" upper="1.0"/>
    <parent link="arm_3_arm1"/>
    <child link="arm_3_arm2"/>
    <axis xyz="1. 0. 0."/>
    <origin xyz="0.0 0.68 0.0" rpy="0.0 0.0 0.0"/>
  </joint>
  <material name="red">
    <color rgba="0.969 0.129 0.122 1.   "/>
  </material>
</robot>
