<?xml version='1.0' encoding='UTF-8'?>
<robot name="estimationBasic">
  <link name="base_link">
    <inertial>
      <origin xyz="0.0 0.0 0.0" rpy="0.0 -0.0 0.0"/>
      <mass value="1.0"/>
      <inertia ixx="1.0" ixy="0.0" ixz="0.0" iyy="1.0" iyz="0.0" izz="1.0"/>
    </inertial>
    <visual>
      <geometry>
        <box size="0.67 0.67 0.3 "/>
      </geometry>
      <material name="red"/>
      <origin xyz="0.0 0.0 0.0" rpy="0.0 -0.0 0.0"/>
    </visual>
    <collision>
      <geometry>
        <box size="0.67 0.67 0.3 "/>
      </geometry>
      <origin xyz="0.0 0.0 0.0" rpy="0.0 0.0 0.0"/>
    </collision>
  </link>
  <link name="set0_arm1">
    <inertial>
      <origin xyz="0.0 0.34 0.0" rpy="0.0 0.0 0.0"/>
      <mass value="1.0"/>
      <inertia ixx="0.0" ixy="0.0" ixz="0.0" iyy="0.0" iyz="0.0" izz="0.0"/>
    </inertial>
    <visual>
      <geometry>
        <box size="0.67 0.67 0.3 "/>
      </geometry>
      <origin xyz="0.0 0.34 0.0" rpy="0.0 0.0 0.0"/>
    </visual>
    <collision>
      <geometry>
        <box size="0.67 0.67 0.3 "/>
      </geometry>
      <origin xyz="0.0 0.34 0.0" rpy="0.0 0.0 0.0"/>
    </collision>
  </link>
  <link name="set0_arm2">
    <inertial>
      <origin xyz="0.0 0.34 0.0" rpy="0.0 0.0 0.0"/>
      <mass value="1.0"/>
      <inertia ixx="0.0" ixy="0.0" ixz="0.0" iyy="0.0" iyz="0.0" izz="0.0"/>
    </inertial>
    <visual>
      <geometry>
        <box size="0.67 0.67 0.3 "/>
      </geometry>
      <origin xyz="0.0 0.34 0.0" rpy="0.0 0.0 0.0"/>
    </visual>
    <collision>
      <geometry>
        <box size="0.67 0.67 0.3 "/>
      </geometry>
      <origin xyz="0.0 0.34 0.0" rpy="0.0 0.0 0.0"/>
    </collision>
  </link>
  <link name="set1_arm1">
    <inertial>
      <origin xyz="0.0 0.34 0.0" rpy="0.0 0.0 0.0"/>
      <mass value="1.0"/>
      <inertia ixx="0.0" ixy="0.0" ixz="0.0" iyy="0.0" iyz="0.0" izz="0.0"/>
    </inertial>
    <visual>
      <geometry>
        <box size="0.67 0.67 0.3 "/>
      </geometry>
      <origin xyz="0.0 0.34 0.0" rpy="0.0 0.0 0.0"/>
    </visual>
    <collision>
      <geometry>
        <box size="0.67 0.67 0.3 "/>
      </geometry>
      <origin xyz="0.0 0.34 0.0" rpy="0.0 0.0 0.0"/>
    </collision>
  </link>
  <link name="set1_arm2">
    <inertial>
      <origin xyz="0.0 0.34 0.0" rpy="0.0 0.0 0.0"/>
      <mass value="1.0"/>
      <inertia ixx="0.0" ixy="0.0" ixz="0.0" iyy="0.0" iyz="0.0" izz="0.0"/>
    </inertial>
    <visual>
      <geometry>
        <box size="0.67 0.67 0.3 "/>
      </geometry>
      <origin xyz="0.0 0.34 0.0" rpy="0.0 0.0 0.0"/>
    </visual>
    <collision>
      <geometry>
        <box size="0.67 0.67 0.3 "/>
      </geometry>
      <origin xyz="0.0 0.34 0.0" rpy="0.0 0.0 0.0"/>
    </collision>
  </link>
  <link name="set2_arm1">
    <inertial>
      <origin xyz="0.0 0.34 0.0" rpy="0.0 0.0 0.0"/>
      <mass value="1.0"/>
      <inertia ixx="0.0" ixy="0.0" ixz="0.0" iyy="0.0" iyz="0.0" izz="0.0"/>
    </inertial>
    <visual>
      <geometry>
        <box size="0.67 0.67 0.3 "/>
      </geometry>
      <origin xyz="0.0 0.34 0.0" rpy="0.0 0.0 0.0"/>
    </visual>
    <collision>
      <geometry>
        <box size="0.67 0.67 0.3 "/>
      </geometry>
      <origin xyz="0.0 0.34 0.0" rpy="0.0 0.0 0.0"/>
    </collision>
  </link>
  <link name="set2_arm2">
    <inertial>
      <origin xyz="0.0 0.34 0.0" rpy="0.0 0.0 0.0"/>
      <mass value="1.0"/>
      <inertia ixx="0.0" ixy="0.0" ixz="0.0" iyy="0.0" iyz="0.0" izz="0.0"/>
    </inertial>
    <visual>
      <geometry>
        <box size="0.67 0.67 0.3 "/>
      </geometry>
      <origin xyz="0.0 0.34 0.0" rpy="0.0 0.0 0.0"/>
    </visual>
    <collision>
      <geometry>
        <box size="0.67 0.67 0.3 "/>
      </geometry>
      <origin xyz="0.0 0.34 0.0" rpy="0.0 0.0 0.0"/>
    </collision>
  </link>
  <link name="set3_arm1">
    <inertial>
      <origin xyz="0.0 0.34 0.0" rpy="0.0 0.0 0.0"/>
      <mass value="1.0"/>
      <inertia ixx="0.0" ixy="0.0" ixz="0.0" iyy="0.0" iyz="0.0" izz="0.0"/>
    </inertial>
    <visual>
      <geometry>
        <box size="0.67 0.67 0.3 "/>
      </geometry>
      <origin xyz="0.0 0.34 0.0" rpy="0.0 0.0 0.0"/>
    </visual>
    <collision>
      <geometry>
        <box size="0.67 0.67 0.3 "/>
      </geometry>
      <origin xyz="0.0 0.34 0.0" rpy="0.0 0.0 0.0"/>
    </collision>
  </link>
  <link name="set3_arm2">
    <inertial>
      <origin xyz="0.0 0.34 0.0" rpy="0.0 0.0 0.0"/>
      <mass value="1.0"/>
      <inertia ixx="0.0" ixy="0.0" ixz="0.0" iyy="0.0" iyz="0.0" izz="0.0"/>
    </inertial>
    <visual>
      <geometry>
        <box size="0.67 0.67 0.3 "/>
      </geometry>
      <origin xyz="0.0 0.34 0.0" rpy="0.0 0.0 0.0"/>
    </visual>
    <collision>
      <geometry>
        <box size="0.67 0.67 0.3 "/>
      </geometry>
      <origin xyz="0.0 0.34 0.0" rpy="0.0 0.0 0.0"/>
    </collision>
  </link>
  <link name="set4_arm1">
    <inertial>
      <origin xyz="0.0 0.34 0.0" rpy="0.0 0.0 0.0"/>
      <mass value="1.0"/>
      <inertia ixx="0.0" ixy="0.0" ixz="0.0" iyy="0.0" iyz="0.0" izz="0.0"/>
    </inertial>
    <visual>
      <geometry>
        <box size="0.67 0.67 0.3 "/>
      </geometry>
      <origin xyz="0.0 0.34 0.0" rpy="0.0 0.0 0.0"/>
    </visual>
    <collision>
      <geometry>
        <box size="0.67 0.67 0.3 "/>
      </geometry>
      <origin xyz="0.0 0.34 0.0" rpy="0.0 0.0 0.0"/>
    </collision>
  </link>
  <link name="set4_arm2">
    <inertial>
      <origin xyz="0.0 0.34 0.0" rpy="0.0 0.0 0.0"/>
      <mass value="1.0"/>
      <inertia ixx="0.0" ixy="0.0" ixz="0.0" iyy="0.0" iyz="0.0" izz="0.0"/>
    </inertial>
    <visual>
      <geometry>
        <box size="0.67 0.67 0.3 "/>
      </geometry>
      <origin xyz="0.0 0.34 0.0" rpy="0.0 0.0 0.0"/>
    </visual>
    <collision>
      <geometry>
        <box size="0.67 0.67 0.3 "/>
      </geometry>
      <origin xyz="0.0 0.34 0.0" rpy="0.0 0.0 0.0"/>
    </collision>
  </link>
  <joint name="set0_jointBase" type="fixed">
    <dynamics damping="0.0" friction="10.0"/>
    <limit effort="1.57" velocity="1.57" lower="-1.57" upper="1.57"/>
    <parent link="base_link"/>
    <child link="set0_arm1"/>
    <axis xyz="1. 0. 0."/>
    <origin xyz="0.0 -0.34 0.0" rpy="0.0 0.0 3.140996777702981"/>
  </joint>
  <joint name="set0_joint1" type="revolute">
    <dynamics damping="0.0" friction="10.0"/>
    <limit effort="1.57" velocity="1.57" lower="-1.57" upper="1.57"/>
    <parent link="set0_arm1"/>
    <child link="set0_arm2"/>
    <axis xyz="1. 0. 0."/>
    <origin xyz="0.0 0.68 0.0" rpy="0.0 0.0 0.0"/>
  </joint>
  <joint name="set1_jointBase" type="fixed">
    <dynamics damping="0.0" friction="10.0"/>
    <limit effort="1.57" velocity="1.57" lower="-1.57" upper="1.57"/>
    <parent link="base_link"/>
    <child link="set1_arm1"/>
    <axis xyz="1. 0. 0."/>
    <origin xyz="-0.34 0.34 0.0" rpy="0.0 0.0 0.9982080703103466"/>
  </joint>
  <joint name="set1_joint1" type="revolute">
    <dynamics damping="0.0" friction="10.0"/>
    <limit effort="1.57" velocity="1.57" lower="-1.57" upper="1.57"/>
    <parent link="set1_arm1"/>
    <child link="set1_arm2"/>
    <axis xyz="1. 0. 0."/>
    <origin xyz="0.0 0.68 0.0" rpy="0.0 0.0 0.0"/>
  </joint>
  <joint name="set2_jointBase" type="fixed">
    <dynamics damping="0.0" friction="10.0"/>
    <limit effort="1.57" velocity="1.57" lower="-1.57" upper="1.57"/>
    <parent link="base_link"/>
    <child link="set2_arm1"/>
    <axis xyz="1. 0. 0."/>
    <origin xyz="0.34 0.34 0.0" rpy="0.0 0.0 -1.0760221271669443"/>
  </joint>
  <joint name="set2_joint1" type="revolute">
    <dynamics damping="0.0" friction="10.0"/>
    <limit effort="1.57" velocity="1.57" lower="-1.57" upper="1.57"/>
    <parent link="set2_arm1"/>
    <child link="set2_arm2"/>
    <axis xyz="1. 0. 0."/>
    <origin xyz="0.0 0.68 0.0" rpy="0.0 0.0 0.0"/>
  </joint>
  <joint name="set3_jointBase" type="fixed">
    <dynamics damping="0.0" friction="10.0"/>
    <limit effort="1.57" velocity="1.57" lower="-1.57" upper="1.57"/>
    <parent link="base_link"/>
    <child link="set3_arm1"/>
    <axis xyz="1. 0. 0."/>
    <origin xyz="0.34 0.34 0.0" rpy="0.0 0.0 -1.0006509717523158"/>
  </joint>
  <joint name="set3_joint1" type="revolute">
    <dynamics damping="0.0" friction="10.0"/>
    <limit effort="1.57" velocity="1.57" lower="-1.57" upper="1.57"/>
    <parent link="set3_arm1"/>
    <child link="set3_arm2"/>
    <axis xyz="1. 0. 0."/>
    <origin xyz="0.0 0.68 0.0" rpy="0.0 0.0 0.0"/>
  </joint>
  <joint name="set4_jointBase" type="fixed">
    <dynamics damping="0.0" friction="10.0"/>
    <limit effort="1.57" velocity="1.57" lower="-1.57" upper="1.57"/>
    <parent link="base_link"/>
    <child link="set4_arm1"/>
    <axis xyz="1. 0. 0."/>
    <origin xyz="-0.34 0.34 0.0" rpy="0.0 0.0 1.0755915533719016"/>
  </joint>
  <joint name="set4_joint1" type="revolute">
    <dynamics damping="0.0" friction="10.0"/>
    <limit effort="1.57" velocity="1.57" lower="-1.57" upper="1.57"/>
    <parent link="set4_arm1"/>
    <child link="set4_arm2"/>
    <axis xyz="1. 0. 0."/>
    <origin xyz="0.0 0.68 0.0" rpy="0.0 0.0 0.0"/>
  </joint>
  <material name="red">
    <color rgba="0.969 0.129 0.122 1.   "/>
  </material>
</robot>
