<?xml version='1.0' encoding='UTF-8'?>
<robot name="rob">
  <link name="set1_arm1">
    <inertial>
      <origin xyz="0.0 0.34 0.0" rpy="0.0 0.0 0.0"/>
      <mass value="1.0"/>
      <inertia ixx="0.0" ixy="0.0" ixz="0.0" iyy="0.0" iyz="0.0" izz="0.0"/>
    </inertial>
    <visual>
      <geometry>
        <box size="0.67 0.67 0.3 "/>
      </geometry>
      <origin xyz="0.0 0.34 0.0" rpy="0.0 0.0 0.0"/>
    </visual>
    <collision>
      <geometry>
        <box size="0.67 0.67 0.3 "/>
      </geometry>
      <origin xyz="0.0 0.34 0.0" rpy="0.0 0.0 0.0"/>
    </collision>
  </link>
  <link name="set1_arm2">
    <inertial>
      <origin xyz="0.0 0.34 0.0" rpy="0.0 0.0 0.0"/>
      <mass value="1.0"/>
      <inertia ixx="0.0" ixy="0.0" ixz="0.0" iyy="0.0" iyz="0.0" izz="0.0"/>
    </inertial>
    <visual>
      <geometry>
        <box size="0.67 0.67 0.3 "/>
      </geometry>
      <origin xyz="0.0 0.34 0.0" rpy="0.0 0.0 0.0"/>
    </visual>
    <collision>
      <geometry>
        <box size="0.67 0.67 0.3 "/>
      </geometry>
      <origin xyz="0.0 0.34 0.0" rpy="0.0 0.0 0.0"/>
    </collision>
  </link>
  <link name="set6_arm1">
    <inertial>
      <origin xyz="0.0 0.34 0.0" rpy="0.0 0.0 0.0"/>
      <mass value="1.0"/>
      <inertia ixx="0.0" ixy="0.0" ixz="0.0" iyy="0.0" iyz="0.0" izz="0.0"/>
    </inertial>
    <visual>
      <geometry>
        <box size="0.67 0.67 0.3 "/>
      </geometry>
      <origin xyz="0.0 0.34 0.0" rpy="0.0 0.0 0.0"/>
    </visual>
    <collision>
      <geometry>
        <box size="0.67 0.67 0.3 "/>
      </geometry>
      <origin xyz="0.0 0.34 0.0" rpy="0.0 0.0 0.0"/>
    </collision>
  </link>
  <link name="set6_arm2">
    <inertial>
      <origin xyz="0.0 0.34 0.0" rpy="0.0 0.0 0.0"/>
      <mass value="1.0"/>
      <inertia ixx="0.0" ixy="0.0" ixz="0.0" iyy="0.0" iyz="0.0" izz="0.0"/>
    </inertial>
    <visual>
      <geometry>
        <box size="0.67 0.67 0.3 "/>
      </geometry>
      <origin xyz="0.0 0.34 0.0" rpy="0.0 0.0 0.0"/>
    </visual>
    <collision>
      <geometry>
        <box size="0.67 0.67 0.3 "/>
      </geometry>
      <origin xyz="0.0 0.34 0.0" rpy="0.0 0.0 0.0"/>
    </collision>
  </link>
  <link name="set8_arm1">
    <inertial>
      <origin xyz="0.0 0.34 0.0" rpy="0.0 0.0 0.0"/>
      <mass value="1.0"/>
      <inertia ixx="0.0" ixy="0.0" ixz="0.0" iyy="0.0" iyz="0.0" izz="0.0"/>
    </inertial>
    <visual>
      <geometry>
        <box size="0.67 0.67 0.3 "/>
      </geometry>
      <origin xyz="0.0 0.34 0.0" rpy="0.0 0.0 0.0"/>
    </visual>
    <collision>
      <geometry>
        <box size="0.67 0.67 0.3 "/>
      </geometry>
      <origin xyz="0.0 0.34 0.0" rpy="0.0 0.0 0.0"/>
    </collision>
  </link>
  <link name="set8_arm2">
    <inertial>
      <origin xyz="0.0 0.34 0.0" rpy="0.0 0.0 0.0"/>
      <mass value="1.0"/>
      <inertia ixx="0.0" ixy="0.0" ixz="0.0" iyy="0.0" iyz="0.0" izz="0.0"/>
    </inertial>
    <visual>
      <geometry>
        <box size="0.67 0.67 0.3 "/>
      </geometry>
      <origin xyz="0.0 0.34 0.0" rpy="0.0 0.0 0.0"/>
    </visual>
    <collision>
      <geometry>
        <box size="0.67 0.67 0.3 "/>
      </geometry>
      <origin xyz="0.0 0.34 0.0" rpy="0.0 0.0 0.0"/>
    </collision>
  </link>
  <link name="base_link">
    <inertial>
      <origin xyz="0.0 0.0 0.0" rpy="0.0 -0.0 0.0"/>
      <mass value="1.0"/>
      <inertia ixx="1.0" ixy="0.0" ixz="0.0" iyy="1.0" iyz="0.0" izz="1.0"/>
    </inertial>
    <visual>
      <geometry>
        <box size="0.67 0.67 0.3 "/>
      </geometry>
      <material name="red"/>
      <origin xyz="0.0 0.0 0.0" rpy="0.0 -0.0 0.0"/>
    </visual>
    <collision>
      <geometry>
        <box size="0.67 0.67 0.3 "/>
      </geometry>
      <origin xyz="0.0 0.0 0.0" rpy="0.0 0.0 0.0"/>
    </collision>
  </link>
  <joint name="set1_jointBase" type="fixed">
    <limit effort="1.57" velocity="1.57" lower="-1.57" upper="1.57"/>
    <parent link="base_link"/>
    <child link="set1_arm1"/>
    <axis xyz="1. 0. 0."/>
    <origin xyz="0.0 0.34 0.0" rpy="0.0 0.0 0.0"/>
  </joint>
  <joint name="set1_joint1" type="revolute">
    <limit effort="1.57" velocity="1.57" lower="-1.57" upper="1.57"/>
    <parent link="set1_arm1"/>
    <child link="set1_arm2"/>
    <axis xyz="1. 0. 0."/>
    <origin xyz="0.0 0.68 0.0" rpy="0.0 0.0 0.0"/>
  </joint>
  <joint name="set6_jointBase" type="fixed">
    <limit effort="1.57" velocity="1.57" lower="-1.57" upper="1.57"/>
    <parent link="base_link"/>
    <child link="set6_arm1"/>
    <axis xyz="1. 0. 0."/>
    <origin xyz="0.34 -0.34 0.0" rpy="0.0 0.0 -2.355"/>
  </joint>
  <joint name="set6_joint1" type="revolute">
    <limit effort="1.57" velocity="1.57" lower="-1.57" upper="1.57"/>
    <parent link="set6_arm1"/>
    <child link="set6_arm2"/>
    <axis xyz="1. 0. 0."/>
    <origin xyz="0.0 0.68 0.0" rpy="0.0 0.0 0.0"/>
  </joint>
  <joint name="set8_jointBase" type="fixed">
    <limit effort="1.57" velocity="1.57" lower="-1.57" upper="1.57"/>
    <parent link="base_link"/>
    <child link="set8_arm1"/>
    <axis xyz="1. 0. 0."/>
    <origin xyz="-0.34 -0.34 0.0" rpy="0.0 0.0 2.355"/>
  </joint>
  <joint name="set8_joint1" type="revolute">
    <limit effort="1.57" velocity="1.57" lower="-1.57" upper="1.57"/>
    <parent link="set8_arm1"/>
    <child link="set8_arm2"/>
    <axis xyz="1. 0. 0."/>
    <origin xyz="0.0 0.68 0.0" rpy="0.0 0.0 0.0"/>
  </joint>
  <material name="red">
    <color rgba="0.969 0.129 0.122 1.   "/>
  </material>
</robot>
