<robot name="robot">

	<!-- * * * Link Definitions * * * -->

 	<link name="base_link">
		<visual>
		    <origin xyz="0 0 0" rpy="0 0 0"/>
         
			<geometry>
				<box size=".67 .67 .3"/>
			</geometry>
			<material name="c">
	       		<color rgba="0 0.9 0.9 1.0"/>
	     	</material>
		</visual>	

    <collision>
      <origin xyz="0 0 0" rpy="0 0 0"/>
      <geometry>
        <box size=".67 .67 .3"/>
      </geometry>
      </collision>

	</link>

<link name="arm1">
		<visual>
		    <origin xyz="0 0 0" rpy="-1 0 0"/>
			<geometry>
				<box size=".68 1.34 .05"/>
			</geometry>
			<material name="Cyan1">
	       		<color rgba="0.3 0.15 0.9 1.0"/>
	     	</material>
		</visual>	
    <collision>
      <origin xyz="0 0 0" rpy="-1 0 0"/>
      <geometry>
        <box size=".68 1.34 .05"/>
      </geometry>
      </collision>

	</link>

  <joint name="joint1" type="revolute">
    <parent link="base_link"/>
    <child link="arm1"/>
    <origin xyz="0.0 0.34 0.0"/>
    <axis xyz="1 0 0"/>
	<limit lower="-.5" upper="1.0" effort="0.0" velocity="0.0"/>

    
  </joint>

</robot>