<robot name="snake">

	<!-- * * * Link Definitions * * * -->

 	<link name="base_link">
		<visual>
		    <origin xyz="0 0 0" rpy="0 0 0.0"/>
         
			<geometry>
				<box size=".67 .67 .3"/>
			</geometry>
			<material name="c">
	       		<color rgba="0 0.9 0.9 1.0"/>
	     	</material>
		</visual>	

    <collision>
      <origin xyz="0 0 0" rpy="0 0 0"/>
      <geometry>
        <box size=".67 .67 .3"/>
      </geometry>
      </collision>

	</link>

	<link name="arm1">
		<visual>
		    <origin xyz="0 .34 0" rpy="0 0 0"/>
			<geometry>
				<box size=".68 .67 .3"/>
			</geometry>
			<material name="Cyan1">
	       		<color rgba="0.3 0.15 0.9 1.0"/>
	     	</material>
		</visual>	

		<collision>
      <origin xyz=".16 0 0" rpy="0 0 1.57"/>
			<geometry>
				<box size=".68 .67 .3"/>
			</geometry>
      </collision>
	</link>

	<link name="body1">
		<visual>
		    <origin xyz="0 .34 0" rpy="0 0 0"/>
			<geometry>
				<box size=".688 .67 .3"/>
			</geometry>
			<material name="Cyan1">
	       		<color rgba="0.3 0.15 0.9 1.0"/>
	     	</material>
		</visual>	

		<collision>
      <origin xyz=".16 0 0" rpy="0 0 0"/>
			<geometry>
				<box size=".68 .67 .3"/>
			</geometry>
      </collision>
	</link>


	<link name="arm2">
		<visual>
		    <origin xyz="0 -.34 0" rpy="0 0 0"/>
			<geometry>
				<box size=".68 .67 .3"/>
			</geometry>
			<material name="Cyan1">
	       		<color rgba="0.3 0.15 0.9 1.0"/>
	     	</material>
		</visual>	

		<collision>
      <origin xyz=".16 0 0" rpy="0 0 0"/>
			<geometry>
				<box size=".68 .67 .3"/>
			</geometry>
      </collision>
	</link>

	<link name="body2">
		<visual>
		    <origin xyz="0 -.34 0" rpy="0 0 0"/>
			<geometry>
				<box size=".688 .67 .3"/>
			</geometry>
			<material name="Cyan1">
	       		<color rgba="0.3 0.15 0.9 1.0"/>
	     	</material>
		</visual>	

		<collision>
      <origin xyz=".16 0 0" rpy="0 0 0"/>
			<geometry>
				<box size=".68 .67 .3"/>
			</geometry>
      </collision>
	</link>

	

  	<joint name="joint1" type="fixed">
    <parent link="base_link"/>
    <child link="arm1"/>
    <origin xyz="0.0 0.34 0"/>
    <axis xyz="1 0 0"/>
	<limit lower="-1" upper="1.0" effort="0.0" velocity="0.0"/> 
  	</joint>

	<joint name="joint2" type="revolute">
    <parent link="arm1"/>
    <child link="body1"/>
    <origin xyz="0.0 0.68 0"/>
    <axis xyz="1 0 0"/>
	<limit lower="-1" upper="1.0" effort="0.0" velocity="0.0"/>
	</joint>

	<joint name="joint3" type="fixed">
    <parent link="base_link"/>
    <child link="arm2"/>
    <origin xyz="0.0 -0.34 0"/>
    <axis xyz="1 0 0"/>
	<limit lower="-1" upper="1.0" effort="0.0" velocity="0.0"/> 
  	</joint>

	<joint name="joint4" type="revolute">
    <parent link="arm2"/>
    <child link="body2"/>
    <origin xyz="0.0 -0.68 0"/>
    <axis xyz="1 0 0"/>
	<limit lower="-1" upper="1.0" effort="0.0" velocity="0.0"/> 
  	</joint>

</robot>